[2025-06-25T09:02:34.154+0200] {taskinstance.py:1103} INFO - Dependencies all met for dep_context=non-requeueable deps ti=<TaskInstance: order_monitoring_dag16.run_dbt_models scheduled__2025-06-25T06:00:00+00:00 [queued]>
[2025-06-25T09:02:34.172+0200] {taskinstance.py:1103} INFO - Dependencies all met for dep_context=requeueable deps ti=<TaskInstance: order_monitoring_dag16.run_dbt_models scheduled__2025-06-25T06:00:00+00:00 [queued]>
[2025-06-25T09:02:34.176+0200] {taskinstance.py:1308} INFO - Starting attempt 1 of 1
[2025-06-25T09:02:34.224+0200] {taskinstance.py:1327} INFO - Executing <Task(BashOperator): run_dbt_models> on 2025-06-25 06:00:00+00:00
[2025-06-25T09:02:34.234+0200] {standard_task_runner.py:57} INFO - Started process 219609 to run task
[2025-06-25T09:02:35.360+0200] {standard_task_runner.py:84} INFO - Running: ['airflow', 'tasks', 'run', 'order_monitoring_dag16', 'run_dbt_models', 'scheduled__2025-06-25T06:00:00+00:00', '--job-id', '30', '--raw', '--subdir', 'DAGS_FOLDER/order_monitoring_dag.py', '--cfg-path', '/tmp/tmphl_jekbr']
[2025-06-25T09:02:35.441+0200] {standard_task_runner.py:85} INFO - Job 30: Subtask run_dbt_models
[2025-06-25T09:02:36.403+0200] {task_command.py:410} INFO - Running <TaskInstance: order_monitoring_dag16.run_dbt_models scheduled__2025-06-25T06:00:00+00:00 [running]> on host 192.168.152.131
[2025-06-25T09:02:43.940+0200] {taskinstance.py:1824} ERROR - Task failed with exception
Traceback (most recent call last):
  File "/home/atef/.local/lib/python3.9/site-packages/sqlalchemy/engine/base.py", line 1905, in _execute_context
    self.dialect.do_execute(
  File "/home/atef/.local/lib/python3.9/site-packages/sqlalchemy/engine/default.py", line 736, in do_execute
    cursor.execute(statement, parameters)
sqlite3.OperationalError: database is locked

The above exception was the direct cause of the following exception:

Traceback (most recent call last):
  File "/home/atef/.local/lib/python3.9/site-packages/airflow/models/taskinstance.py", line 1407, in _run_raw_task
    self._execute_task_with_callbacks(context, test_mode)
  File "/home/atef/.local/lib/python3.9/site-packages/airflow/models/taskinstance.py", line 1525, in _execute_task_with_callbacks
    self.clear_xcom_data()
  File "/home/atef/.local/lib/python3.9/site-packages/airflow/utils/session.py", line 76, in wrapper
    return func(*args, session=session, **kwargs)
  File "/home/atef/.local/lib/python3.9/site-packages/airflow/models/taskinstance.py", line 873, in clear_xcom_data
    XCom.clear(
  File "/home/atef/.local/lib/python3.9/site-packages/airflow/utils/session.py", line 73, in wrapper
    return func(*args, **kwargs)
  File "/home/atef/.local/lib/python3.9/site-packages/airflow/api_internal/internal_api_call.py", line 112, in wrapper
    return func(*args, **kwargs)
  File "/home/atef/.local/lib/python3.9/site-packages/airflow/models/xcom.py", line 616, in clear
    query.delete()
  File "/home/atef/.local/lib/python3.9/site-packages/sqlalchemy/orm/query.py", line 3222, in delete
    result = self.session.execute(
  File "/home/atef/.local/lib/python3.9/site-packages/sqlalchemy/orm/session.py", line 1717, in execute
    result = conn._execute_20(statement, params or {}, execution_options)
  File "/home/atef/.local/lib/python3.9/site-packages/sqlalchemy/engine/base.py", line 1710, in _execute_20
    return meth(self, args_10style, kwargs_10style, execution_options)
  File "/home/atef/.local/lib/python3.9/site-packages/sqlalchemy/sql/elements.py", line 334, in _execute_on_connection
    return connection._execute_clauseelement(
  File "/home/atef/.local/lib/python3.9/site-packages/sqlalchemy/engine/base.py", line 1577, in _execute_clauseelement
    ret = self._execute_context(
  File "/home/atef/.local/lib/python3.9/site-packages/sqlalchemy/engine/base.py", line 1948, in _execute_context
    self._handle_dbapi_exception(
  File "/home/atef/.local/lib/python3.9/site-packages/sqlalchemy/engine/base.py", line 2129, in _handle_dbapi_exception
    util.raise_(
  File "/home/atef/.local/lib/python3.9/site-packages/sqlalchemy/util/compat.py", line 211, in raise_
    raise exception
  File "/home/atef/.local/lib/python3.9/site-packages/sqlalchemy/engine/base.py", line 1905, in _execute_context
    self.dialect.do_execute(
  File "/home/atef/.local/lib/python3.9/site-packages/sqlalchemy/engine/default.py", line 736, in do_execute
    cursor.execute(statement, parameters)
sqlalchemy.exc.OperationalError: (sqlite3.OperationalError) database is locked
[SQL: DELETE FROM xcom WHERE xcom.dag_id = ? AND xcom.task_id = ? AND xcom.run_id = ?]
[parameters: ('order_monitoring_dag16', 'run_dbt_models', 'scheduled__2025-06-25T06:00:00+00:00')]
(Background on this error at: https://sqlalche.me/e/14/e3q8)
[2025-06-25T09:02:52.816+0200] {taskinstance.py:1345} INFO - Marking task as FAILED. dag_id=order_monitoring_dag16, task_id=run_dbt_models, execution_date=20250625T060000, start_date=20250625T070234, end_date=20250625T070252
[2025-06-25T09:03:10.420+0200] {logging_mixin.py:149} WARNING - /home/atef/.local/lib/python3.9/site-packages/airflow/utils/email.py:152 RemovedInAirflow3Warning: Fetching SMTP credentials from configuration variables will be deprecated in a future release. Please set credentials using a connection instead.
[2025-06-25T09:03:10.639+0200] {configuration.py:676} WARNING - section/key [smtp/smtp_user] not found in config
[2025-06-25T09:02:55.068+0200] {job.py:216} ERROR - Job heartbeat got an exception
Traceback (most recent call last):
  File "/home/atef/.local/lib/python3.9/site-packages/sqlalchemy/engine/base.py", line 1905, in _execute_context
    self.dialect.do_execute(
  File "/home/atef/.local/lib/python3.9/site-packages/sqlalchemy/engine/default.py", line 736, in do_execute
    cursor.execute(statement, parameters)
sqlite3.OperationalError: database is locked

The above exception was the direct cause of the following exception:

Traceback (most recent call last):
  File "/home/atef/.local/lib/python3.9/site-packages/airflow/jobs/job.py", line 208, in heartbeat
    session.commit()
  File "/home/atef/.local/lib/python3.9/site-packages/sqlalchemy/orm/session.py", line 1454, in commit
    self._transaction.commit(_to_root=self.future)
  File "/home/atef/.local/lib/python3.9/site-packages/sqlalchemy/orm/session.py", line 832, in commit
    self._prepare_impl()
  File "/home/atef/.local/lib/python3.9/site-packages/sqlalchemy/orm/session.py", line 811, in _prepare_impl
    self.session.flush()
  File "/home/atef/.local/lib/python3.9/site-packages/sqlalchemy/orm/session.py", line 3449, in flush
    self._flush(objects)
  File "/home/atef/.local/lib/python3.9/site-packages/sqlalchemy/orm/session.py", line 3589, in _flush
    transaction.rollback(_capture_exception=True)
  File "/home/atef/.local/lib/python3.9/site-packages/sqlalchemy/util/langhelpers.py", line 70, in __exit__
    compat.raise_(
  File "/home/atef/.local/lib/python3.9/site-packages/sqlalchemy/util/compat.py", line 211, in raise_
    raise exception
  File "/home/atef/.local/lib/python3.9/site-packages/sqlalchemy/orm/session.py", line 3549, in _flush
    flush_context.execute()
  File "/home/atef/.local/lib/python3.9/site-packages/sqlalchemy/orm/unitofwork.py", line 456, in execute
    rec.execute(self)
  File "/home/atef/.local/lib/python3.9/site-packages/sqlalchemy/orm/unitofwork.py", line 630, in execute
    util.preloaded.orm_persistence.save_obj(
  File "/home/atef/.local/lib/python3.9/site-packages/sqlalchemy/orm/persistence.py", line 237, in save_obj
    _emit_update_statements(
  File "/home/atef/.local/lib/python3.9/site-packages/sqlalchemy/orm/persistence.py", line 1001, in _emit_update_statements
    c = connection._execute_20(
  File "/home/atef/.local/lib/python3.9/site-packages/sqlalchemy/engine/base.py", line 1710, in _execute_20
    return meth(self, args_10style, kwargs_10style, execution_options)
  File "/home/atef/.local/lib/python3.9/site-packages/sqlalchemy/sql/elements.py", line 334, in _execute_on_connection
    return connection._execute_clauseelement(
  File "/home/atef/.local/lib/python3.9/site-packages/sqlalchemy/engine/base.py", line 1577, in _execute_clauseelement
    ret = self._execute_context(
  File "/home/atef/.local/lib/python3.9/site-packages/sqlalchemy/engine/base.py", line 1948, in _execute_context
    self._handle_dbapi_exception(
  File "/home/atef/.local/lib/python3.9/site-packages/sqlalchemy/engine/base.py", line 2129, in _handle_dbapi_exception
    util.raise_(
  File "/home/atef/.local/lib/python3.9/site-packages/sqlalchemy/util/compat.py", line 211, in raise_
    raise exception
  File "/home/atef/.local/lib/python3.9/site-packages/sqlalchemy/engine/base.py", line 1905, in _execute_context
    self.dialect.do_execute(
  File "/home/atef/.local/lib/python3.9/site-packages/sqlalchemy/engine/default.py", line 736, in do_execute
    cursor.execute(statement, parameters)
sqlalchemy.exc.OperationalError: (sqlite3.OperationalError) database is locked
[SQL: UPDATE job SET latest_heartbeat=? WHERE job.id = ?]
[parameters: ('2025-06-25 07:02:41.944036', 30)]
(Background on this error at: https://sqlalche.me/e/14/e3q8)
[2025-06-25T09:03:10.695+0200] {email.py:268} INFO - Email alerting: attempt 1
[2025-06-25T09:03:10.807+0200] {configuration.py:676} WARNING - section/key [smtp/smtp_user] not found in config
[2025-06-25T09:03:10.829+0200] {email.py:268} INFO - Email alerting: attempt 1
[2025-06-25T09:03:10.832+0200] {taskinstance.py:1889} ERROR - Failed to send email to: ['imamzafar100@gmail.com']
Traceback (most recent call last):
  File "/home/atef/.local/lib/python3.9/site-packages/sqlalchemy/engine/base.py", line 1905, in _execute_context
    self.dialect.do_execute(
  File "/home/atef/.local/lib/python3.9/site-packages/sqlalchemy/engine/default.py", line 736, in do_execute
    cursor.execute(statement, parameters)
sqlite3.OperationalError: database is locked

The above exception was the direct cause of the following exception:

Traceback (most recent call last):
  File "/home/atef/.local/lib/python3.9/site-packages/airflow/models/taskinstance.py", line 1407, in _run_raw_task
    self._execute_task_with_callbacks(context, test_mode)
  File "/home/atef/.local/lib/python3.9/site-packages/airflow/models/taskinstance.py", line 1525, in _execute_task_with_callbacks
    self.clear_xcom_data()
  File "/home/atef/.local/lib/python3.9/site-packages/airflow/utils/session.py", line 76, in wrapper
    return func(*args, session=session, **kwargs)
  File "/home/atef/.local/lib/python3.9/site-packages/airflow/models/taskinstance.py", line 873, in clear_xcom_data
    XCom.clear(
  File "/home/atef/.local/lib/python3.9/site-packages/airflow/utils/session.py", line 73, in wrapper
    return func(*args, **kwargs)
  File "/home/atef/.local/lib/python3.9/site-packages/airflow/api_internal/internal_api_call.py", line 112, in wrapper
    return func(*args, **kwargs)
  File "/home/atef/.local/lib/python3.9/site-packages/airflow/models/xcom.py", line 616, in clear
    query.delete()
  File "/home/atef/.local/lib/python3.9/site-packages/sqlalchemy/orm/query.py", line 3222, in delete
    result = self.session.execute(
  File "/home/atef/.local/lib/python3.9/site-packages/sqlalchemy/orm/session.py", line 1717, in execute
    result = conn._execute_20(statement, params or {}, execution_options)
  File "/home/atef/.local/lib/python3.9/site-packages/sqlalchemy/engine/base.py", line 1710, in _execute_20
    return meth(self, args_10style, kwargs_10style, execution_options)
  File "/home/atef/.local/lib/python3.9/site-packages/sqlalchemy/sql/elements.py", line 334, in _execute_on_connection
    return connection._execute_clauseelement(
  File "/home/atef/.local/lib/python3.9/site-packages/sqlalchemy/engine/base.py", line 1577, in _execute_clauseelement
    ret = self._execute_context(
  File "/home/atef/.local/lib/python3.9/site-packages/sqlalchemy/engine/base.py", line 1948, in _execute_context
    self._handle_dbapi_exception(
  File "/home/atef/.local/lib/python3.9/site-packages/sqlalchemy/engine/base.py", line 2129, in _handle_dbapi_exception
    util.raise_(
  File "/home/atef/.local/lib/python3.9/site-packages/sqlalchemy/util/compat.py", line 211, in raise_
    raise exception
  File "/home/atef/.local/lib/python3.9/site-packages/sqlalchemy/engine/base.py", line 1905, in _execute_context
    self.dialect.do_execute(
  File "/home/atef/.local/lib/python3.9/site-packages/sqlalchemy/engine/default.py", line 736, in do_execute
    cursor.execute(statement, parameters)
sqlalchemy.exc.OperationalError: (sqlite3.OperationalError) database is locked
[SQL: DELETE FROM xcom WHERE xcom.dag_id = ? AND xcom.task_id = ? AND xcom.run_id = ?]
[parameters: ('order_monitoring_dag16', 'run_dbt_models', 'scheduled__2025-06-25T06:00:00+00:00')]
(Background on this error at: https://sqlalche.me/e/14/e3q8)

During handling of the above exception, another exception occurred:

Traceback (most recent call last):
  File "/home/atef/.local/lib/python3.9/site-packages/airflow/models/taskinstance.py", line 2295, in email_alert
    send_email(task.email, subject, html_content)
  File "/home/atef/.local/lib/python3.9/site-packages/airflow/utils/email.py", line 78, in send_email
    return backend(
  File "/home/atef/.local/lib/python3.9/site-packages/airflow/utils/email.py", line 152, in send_email_smtp
    send_mime_email(e_from=mail_from, e_to=recipients, mime_msg=msg, conn_id=conn_id, dryrun=dryrun)
  File "/home/atef/.local/lib/python3.9/site-packages/airflow/utils/email.py", line 270, in send_mime_email
    smtp_conn = _get_smtp_connection(smtp_host, smtp_port, smtp_timeout, smtp_ssl)
  File "/home/atef/.local/lib/python3.9/site-packages/airflow/utils/email.py", line 317, in _get_smtp_connection
    else smtplib.SMTP(host=host, port=port, timeout=timeout)
  File "/usr/lib64/python3.9/smtplib.py", line 255, in __init__
    (code, msg) = self.connect(host, port)
  File "/usr/lib64/python3.9/smtplib.py", line 341, in connect
    self.sock = self._get_socket(host, port, self.timeout)
  File "/usr/lib64/python3.9/smtplib.py", line 312, in _get_socket
    return socket.create_connection((host, port), timeout,
  File "/usr/lib64/python3.9/socket.py", line 856, in create_connection
    raise err
  File "/usr/lib64/python3.9/socket.py", line 844, in create_connection
    sock.connect(sa)
ConnectionRefusedError: [Errno 111] Connection refused

During handling of the above exception, another exception occurred:

Traceback (most recent call last):
  File "/home/atef/.local/lib/python3.9/site-packages/airflow/models/taskinstance.py", line 1887, in handle_failure
    self.email_alert(error, task)
  File "/home/atef/.local/lib/python3.9/site-packages/airflow/models/taskinstance.py", line 2297, in email_alert
    send_email(task.email, subject, html_content_err)
  File "/home/atef/.local/lib/python3.9/site-packages/airflow/utils/email.py", line 78, in send_email
    return backend(
  File "/home/atef/.local/lib/python3.9/site-packages/airflow/utils/email.py", line 152, in send_email_smtp
    send_mime_email(e_from=mail_from, e_to=recipients, mime_msg=msg, conn_id=conn_id, dryrun=dryrun)
  File "/home/atef/.local/lib/python3.9/site-packages/airflow/utils/email.py", line 270, in send_mime_email
    smtp_conn = _get_smtp_connection(smtp_host, smtp_port, smtp_timeout, smtp_ssl)
  File "/home/atef/.local/lib/python3.9/site-packages/airflow/utils/email.py", line 317, in _get_smtp_connection
    else smtplib.SMTP(host=host, port=port, timeout=timeout)
  File "/usr/lib64/python3.9/smtplib.py", line 255, in __init__
    (code, msg) = self.connect(host, port)
  File "/usr/lib64/python3.9/smtplib.py", line 341, in connect
    self.sock = self._get_socket(host, port, self.timeout)
  File "/usr/lib64/python3.9/smtplib.py", line 312, in _get_socket
    return socket.create_connection((host, port), timeout,
  File "/usr/lib64/python3.9/socket.py", line 856, in create_connection
    raise err
  File "/usr/lib64/python3.9/socket.py", line 844, in create_connection
    sock.connect(sa)
ConnectionRefusedError: [Errno 111] Connection refused
[2025-06-25T09:03:11.628+0200] {standard_task_runner.py:104} ERROR - Failed to execute job 30 for task run_dbt_models ((sqlite3.OperationalError) database is locked
[SQL: DELETE FROM xcom WHERE xcom.dag_id = ? AND xcom.task_id = ? AND xcom.run_id = ?]
[parameters: ('order_monitoring_dag16', 'run_dbt_models', 'scheduled__2025-06-25T06:00:00+00:00')]
(Background on this error at: https://sqlalche.me/e/14/e3q8); 219609)
[2025-06-25T09:03:11.655+0200] {local_task_job_runner.py:225} INFO - Task exited with return code 1
[2025-06-25T09:03:11.741+0200] {taskinstance.py:2651} INFO - 0 downstream tasks scheduled from follow-on schedule check
