[2025-06-25T01:59:14.140+0200] {taskinstance.py:1103} INFO - Dependencies all met for dep_context=non-requeueable deps ti=<TaskInstance: order_monitoring_dag16.check_delayed_orders manual__2025-06-24T23:58:33.725867+00:00 [queued]>
[2025-06-25T01:59:14.161+0200] {taskinstance.py:1103} INFO - Dependencies all met for dep_context=requeueable deps ti=<TaskInstance: order_monitoring_dag16.check_delayed_orders manual__2025-06-24T23:58:33.725867+00:00 [queued]>
[2025-06-25T01:59:14.162+0200] {taskinstance.py:1308} INFO - Starting attempt 1 of 1
[2025-06-25T01:59:14.195+0200] {taskinstance.py:1327} INFO - Executing <Task(BashOperator): check_delayed_orders> on 2025-06-24 23:58:33.725867+00:00
[2025-06-25T01:59:14.201+0200] {standard_task_runner.py:57} INFO - Started process 192511 to run task
[2025-06-25T01:59:14.238+0200] {standard_task_runner.py:84} INFO - Running: ['airflow', 'tasks', 'run', 'order_monitoring_dag16', 'check_delayed_orders', 'manual__2025-06-24T23:58:33.725867+00:00', '--job-id', '15', '--raw', '--subdir', 'DAGS_FOLDER/order_monitoring_dag.py', '--cfg-path', '/tmp/tmpsrfw49rz']
[2025-06-25T01:59:14.247+0200] {standard_task_runner.py:85} INFO - Job 15: Subtask check_delayed_orders
[2025-06-25T01:59:14.428+0200] {task_command.py:410} INFO - Running <TaskInstance: order_monitoring_dag16.check_delayed_orders manual__2025-06-24T23:58:33.725867+00:00 [running]> on host 192.168.152.131
[2025-06-25T01:59:14.570+0200] {taskinstance.py:1545} INFO - Exporting env vars: AIRFLOW_CTX_DAG_EMAIL='imamzafar100@gmail.com' AIRFLOW_CTX_DAG_OWNER='airflow' AIRFLOW_CTX_DAG_ID='order_monitoring_dag16' AIRFLOW_CTX_TASK_ID='check_delayed_orders' AIRFLOW_CTX_EXECUTION_DATE='2025-06-24T23:58:33.725867+00:00' AIRFLOW_CTX_TRY_NUMBER='1' AIRFLOW_CTX_DAG_RUN_ID='manual__2025-06-24T23:58:33.725867+00:00'
[2025-06-25T01:59:14.577+0200] {subprocess.py:63} INFO - Tmp dir root location: 
 /tmp
[2025-06-25T01:59:14.579+0200] {subprocess.py:75} INFO - Running command: ['/usr/bin/bash', '-c', 'source "/home/atef/project/E-Commerce-Order-Pipeline/airflow_venv_39/bin/activate" && python "/home/atef/project/E-Commerce-Order-Pipeline/airflow_project/dags/utils/check_delayed_orders.py"']
[2025-06-25T01:59:14.602+0200] {subprocess.py:86} INFO - Output:
[2025-06-25T01:59:31.556+0200] {subprocess.py:93} INFO - ✅ Running Snowflake delayed orders check...
[2025-06-25T01:59:31.557+0200] {subprocess.py:93} INFO - ✅ Python path: /usr/bin/python
[2025-06-25T01:59:31.558+0200] {subprocess.py:93} INFO - ✅ Snowflake connector version: 3.15.0
[2025-06-25T01:59:31.558+0200] {subprocess.py:93} INFO - ✅ Connected to Snowflake
[2025-06-25T01:59:31.558+0200] {subprocess.py:93} INFO - ✅ Query Result: (1,)
[2025-06-25T01:59:31.558+0200] {subprocess.py:93} INFO - ❌ Error: 1 delayed orders found.
[2025-06-25T01:59:31.687+0200] {subprocess.py:97} INFO - Command exited with return code 1
[2025-06-25T01:59:31.760+0200] {taskinstance.py:1824} ERROR - Task failed with exception
Traceback (most recent call last):
  File "/home/atef/.local/lib/python3.9/site-packages/airflow/operators/bash.py", line 210, in execute
    raise AirflowException(
airflow.exceptions.AirflowException: Bash command failed. The command returned a non-zero exit code 1.
[2025-06-25T01:59:31.775+0200] {taskinstance.py:1345} INFO - Marking task as FAILED. dag_id=order_monitoring_dag16, task_id=check_delayed_orders, execution_date=20250624T235833, start_date=20250624T235914, end_date=20250624T235931
[2025-06-25T01:59:31.887+0200] {logging_mixin.py:149} WARNING - /home/atef/.local/lib/python3.9/site-packages/airflow/utils/email.py:152 RemovedInAirflow3Warning: Fetching SMTP credentials from configuration variables will be deprecated in a future release. Please set credentials using a connection instead.
[2025-06-25T01:59:31.891+0200] {configuration.py:676} WARNING - section/key [smtp/smtp_user] not found in config
[2025-06-25T01:59:31.892+0200] {email.py:268} INFO - Email alerting: attempt 1
[2025-06-25T01:59:31.920+0200] {configuration.py:676} WARNING - section/key [smtp/smtp_user] not found in config
[2025-06-25T01:59:31.921+0200] {email.py:268} INFO - Email alerting: attempt 1
[2025-06-25T01:59:31.922+0200] {taskinstance.py:1889} ERROR - Failed to send email to: ['imamzafar100@gmail.com']
Traceback (most recent call last):
  File "/home/atef/.local/lib/python3.9/site-packages/airflow/models/taskinstance.py", line 1407, in _run_raw_task
    self._execute_task_with_callbacks(context, test_mode)
  File "/home/atef/.local/lib/python3.9/site-packages/airflow/models/taskinstance.py", line 1558, in _execute_task_with_callbacks
    result = self._execute_task(context, task_orig)
  File "/home/atef/.local/lib/python3.9/site-packages/airflow/models/taskinstance.py", line 1628, in _execute_task
    result = execute_callable(context=context)
  File "/home/atef/.local/lib/python3.9/site-packages/airflow/operators/bash.py", line 210, in execute
    raise AirflowException(
airflow.exceptions.AirflowException: Bash command failed. The command returned a non-zero exit code 1.

During handling of the above exception, another exception occurred:

Traceback (most recent call last):
  File "/home/atef/.local/lib/python3.9/site-packages/airflow/models/taskinstance.py", line 2295, in email_alert
    send_email(task.email, subject, html_content)
  File "/home/atef/.local/lib/python3.9/site-packages/airflow/utils/email.py", line 78, in send_email
    return backend(
  File "/home/atef/.local/lib/python3.9/site-packages/airflow/utils/email.py", line 152, in send_email_smtp
    send_mime_email(e_from=mail_from, e_to=recipients, mime_msg=msg, conn_id=conn_id, dryrun=dryrun)
  File "/home/atef/.local/lib/python3.9/site-packages/airflow/utils/email.py", line 270, in send_mime_email
    smtp_conn = _get_smtp_connection(smtp_host, smtp_port, smtp_timeout, smtp_ssl)
  File "/home/atef/.local/lib/python3.9/site-packages/airflow/utils/email.py", line 317, in _get_smtp_connection
    else smtplib.SMTP(host=host, port=port, timeout=timeout)
  File "/usr/lib64/python3.9/smtplib.py", line 255, in __init__
    (code, msg) = self.connect(host, port)
  File "/usr/lib64/python3.9/smtplib.py", line 341, in connect
    self.sock = self._get_socket(host, port, self.timeout)
  File "/usr/lib64/python3.9/smtplib.py", line 312, in _get_socket
    return socket.create_connection((host, port), timeout,
  File "/usr/lib64/python3.9/socket.py", line 856, in create_connection
    raise err
  File "/usr/lib64/python3.9/socket.py", line 844, in create_connection
    sock.connect(sa)
ConnectionRefusedError: [Errno 111] Connection refused

During handling of the above exception, another exception occurred:

Traceback (most recent call last):
  File "/home/atef/.local/lib/python3.9/site-packages/airflow/models/taskinstance.py", line 1887, in handle_failure
    self.email_alert(error, task)
  File "/home/atef/.local/lib/python3.9/site-packages/airflow/models/taskinstance.py", line 2297, in email_alert
    send_email(task.email, subject, html_content_err)
  File "/home/atef/.local/lib/python3.9/site-packages/airflow/utils/email.py", line 78, in send_email
    return backend(
  File "/home/atef/.local/lib/python3.9/site-packages/airflow/utils/email.py", line 152, in send_email_smtp
    send_mime_email(e_from=mail_from, e_to=recipients, mime_msg=msg, conn_id=conn_id, dryrun=dryrun)
  File "/home/atef/.local/lib/python3.9/site-packages/airflow/utils/email.py", line 270, in send_mime_email
    smtp_conn = _get_smtp_connection(smtp_host, smtp_port, smtp_timeout, smtp_ssl)
  File "/home/atef/.local/lib/python3.9/site-packages/airflow/utils/email.py", line 317, in _get_smtp_connection
    else smtplib.SMTP(host=host, port=port, timeout=timeout)
  File "/usr/lib64/python3.9/smtplib.py", line 255, in __init__
    (code, msg) = self.connect(host, port)
  File "/usr/lib64/python3.9/smtplib.py", line 341, in connect
    self.sock = self._get_socket(host, port, self.timeout)
  File "/usr/lib64/python3.9/smtplib.py", line 312, in _get_socket
    return socket.create_connection((host, port), timeout,
  File "/usr/lib64/python3.9/socket.py", line 856, in create_connection
    raise err
  File "/usr/lib64/python3.9/socket.py", line 844, in create_connection
    sock.connect(sa)
ConnectionRefusedError: [Errno 111] Connection refused
[2025-06-25T01:59:32.021+0200] {standard_task_runner.py:104} ERROR - Failed to execute job 15 for task check_delayed_orders (Bash command failed. The command returned a non-zero exit code 1.; 192511)
[2025-06-25T01:59:32.083+0200] {local_task_job_runner.py:225} INFO - Task exited with return code 1
[2025-06-25T01:59:32.166+0200] {taskinstance.py:2651} INFO - 0 downstream tasks scheduled from follow-on schedule check
